Workbook

Sheet Timesheet
A1: Timesheet
A7: 1 . IDENTIFICAÇÃO DO COLABORADOR
A8: Departamento - Área | C8: 2023
A9: Nome
A11: 2. LISTA DE ACTIVIDADES REALIZADAS
A12: Data | B12: Descrição | C12: Tipo | D12: Início | E12: Fim | F12: Total (horas) | G12: Comentários/Notas
A13: 45019 | B13: Instalar na maquina o projecto de automação da primeira versão de account-opening | C13: Execução | D13: 0.42708333 | E13: 0.70138889 | F13: =E13-D13 -> 0.27430556
A14: 45019 | B14: Configurações do maven , proxy, Java e IDE´s (Ajuda do Helénio) | C14: Execução | D14: 0.57291667 | E14: 0.625 | F14: =E14-D14 -> 0.052083333
A15: 45019 | B15: Leitura da documentação do WF de abertura de contas (Enviado pela Lara) | C15: Análise | D15: 0.65347222 | E15: 0.6875 | F15: =E15-D15 -> 0.034027778
A16: 45020 | B16: Solicitei permissões para dar continuidades a instalação e configuração do projecto opening-account e suas dependencias | C16: Suporte | D16: 0.38541667 | E16: 0.58333333 | F16: =E16-D16 -> 0.19791667
A17: 45020 | B17: Pedido de acesso ao WF nos ambientes de Qualidade e Pré-Produção (Arménio Julião) | C17: Suporte | D17: 0.46041667 | E17: 0.46388889 | F17: =E17-D17 -> 0.0034722222
A18: 45021 | B18: Acesso ao MozaDesk | C18: Suporte | D18: 0.46388889 | E18: 0.46527778 | F18: =E18-D18 -> 0.0013888889
A19: 45021 | B19: Definição de Qualidade - Comentários (Referente ao documento partilhado pela Lara com fluxo de trabalho da Aréa) | C19: Elaboração | D19: 0.63888889 | E19: 0.67986111 | F19: =E19-D19 -> 0.040972222
A20: 45022 | B20: Pedido de adição do meu user ao grupo de PJ-2018-010 – Workflow de Processos | Relatório de Progresso | C20: Suporte | D20: 0.48819444 | E20: 0.50347222 | F20: =E20-D20 -> 0.015277778
A21: 45022 | B21: Uma proposta de melhores praticas para nossa aréa de qualidade | C21: Elaboração | D21: 0.36111111 | E21: 0.63888889 | F21: =E21-D21 -> 0.27777778
A22: 45028 | B22: Validação dos Jiras com a DOP para aceitação com o colega Osvaldo | C22: Suporte | F22: =E22-D22 -> 0
A23: 45029 | B23: Validação da correção de bugs no WF - no processo de devoluçao de uma conta através do serviço de clientes para UN (Com o colega Osvaldo Matola a pedido da Lara e Ineida) | C23: Execução | D23: 0.56944444 | E23: 0.61805556 | F23: =E23-D23 -> 0.048611111
A24: 45030 | B24: Documentação do WF - Meios de Pagamentos | C24: Análise | D24: 0.52361111 | E24: 0.6875 | F24: =E24-D24 -> 0.16388889
A25: 45030 | B25: Validação na lentidão para finalizar os processos a nivel do workflow com o colega (Jacenio Mazivila) | C25: Suporte | D25: 0.57916667 | E25: 0.59027778 | F25: =E25-D25 -> 0.011111111
A26: 45030 | B26: Novo codigo para automatizar o WF - Opening account e Meios de Pagamento (Nodejs - Cypress - Mochaawesome-reporter) | C26: Execução | D26: 0.39583333 | E26: 0.52083333 | F26: =E26-D26 -> 0.125
F27: =E27-D27 -> 0
F28: =E28-D28 -> 0
F29: =E29-D29 -> 0
F30: =E30-D30 -> 0
F31: =E31-D31 -> 0
F32: =E32-D32 -> 0
F33: =E33-D33 -> 0
F34: =E34-D34 -> 0
F35: =E35-D35 -> 0
F36: =E36-D36 -> 0
F37: =E37-D37 -> 0
F38: =E38-D38 -> 0
... F296: =E296-D296 -> 0
F297: =E297-D297 -> 0 | G297: Cláudia Tivane
F298: =E298-D298 -> 0
F299: =E299-D299 -> 0 | G299: Edson Uamusse
F300: =E300-D300 -> 0
F301: =E301-D301 -> 0
F302: =E302-D302 -> 0
F303: =E303-D303 -> 0
...

Sheet Mês 1
A2: Mês | B2: Janeiro | O2: Mês | P2: Fevereiro
A3: Data | B3: Análise | C3: Elaboração | D3: Gestão | E3: Outro | F3: Reunião | G3: Revisão | H3: Suporte | I3: Execução | J3: Pesquisa | K3: Total | L3: Entrada | M3: Saída | O3: Data | P3: Análise | Q3: Elaboração | R3: Gestão | S3: Outro | T3: Reunião | U3: Revisão | V3: Suporte | W3: Execução | X3: Pesquisa | Y3: Total | Z3: Entrada | AA3: Saída
A4: 44927 | B4: =SUMIFS(Timesheet!$F$13:$F$11461,Timesheet!$A$13:$A$11461,'Mês 1'!A4,Timesheet!$C$13:$C$11461,'Mês 1'!$B$40) -> 0 | C4: =SUMIFS(Timesheet!$F$13:$F$11461,Timesheet!$A$13:$A$11461,'Mês 1'!A4,Timesheet!$C$13:$C$11461,'Mês 1'!$C$40) -> 0 | D4: =SUMIFS(Timesheet!$F$13:$F$11461,Timesheet!$A$13:$A$11461,'Mês 1'!A4,Timesheet!$C$13:$C$11461,'Mês 1'!$D$40) -> 0 | E4: =SUMIFS(Timesheet!$F$13:$F$11461,Timesheet!$A$13:$A$11461,'Mês 1'!A4,Timesheet!$C$13:$C$11461,'Mês 1'!$E$40) -> 0 | F4: =SUMIFS(Timesheet!$F$13:$F$11461,Timesheet!$A$13:$A$11461,'Mês 1'!A4,Timesheet!$C$13:$C$11461,'Mês 1'!$F$40) -> 0 | G4: =SUMIFS(Timesheet!$F$13:$F$11461,Timesheet!$A$13:$A$11461,'Mês 1'!A4,Timesheet!$C$13:$C$11461,'Mês 1'!$G$40) -> 0 | H4: =SUMIFS(Timesheet!$F$13:$F$2615,Timesheet!$A$13:$A$2615,'Mês 1'!A4,Timesheet!$C$13:$C$2615,'Mês 1'!$H$3) -> 0 | I4: =SUMIFS(Timesheet!$F$13:$F$2615,Timesheet!$A$13:$A$2615,'Mês 1'!A4,Timesheet!$C$13:$C$2615,'Mês 1'!$I$3) -> 0 | J4: =SUMIFS(Timesheet!$F$13:$F$2615,Timesheet!$A$13:$A$2615,'Mês 1'!A4,Timesheet!$C$13:$C$2615,'Mês 1'!$J$3) -> 0 | K4: =SUM(B4:I4) -> 0 | L4: {=MIN(IF(Timesheet!$A$13:$A$11483='Mês 1'!A4,Timesheet!$D$13:$D$11483))} -> 0 | M4: {=MAX(IF(Timesheet!$A$13:$A$11483='Mês 1'!A4,Timesheet!$E$13:$E$11483))} -> 0 | O4: 44958 | P4: =SUMIFS(Timesheet!$F$13:$F$11461,Timesheet!$A$13:$A$11461,'Mês 1'!O4,Timesheet!$C$13:$C$11461,'Mês 1'!$B$40) -> 0 | Q4: =SUMIFS(Timesheet!$F$13:$F$11461,Timesheet!$A$13:$A$11461,'Mês 1'!O4,Timesheet!$C$13:$C$11461,'Mês 1'!$C$40) -> 0 | R4: =SUMIFS(Timesheet!$F$13:$F$11461,Timesheet!$A$13:$A$11461,'Mês 1'!O4,Timesheet!$C$13:$C$11461,'Mês 1'!$D$40) -> 0 | S4: =SUMIFS(Timesheet!$F$13:$F$11461,Timesheet!$A$13:$A$11461,'Mês 1'!O4,Timesheet!$C$13:$C$11461,'Mês 1'!$E$40) -> 0 | T4: =SUMIFS(Timesheet!$F$13:$F$11461,Timesheet!$A$13:$A$11461,'Mês 1'!O4,Timesheet!$C$13:$C$11461,'Mês 1'!$F$40) -> 0 | U4: =SUMIFS(Timesheet!$F$13:$F$11461,Timesheet!$A$13:$A$11461,'Mês 1'!O4,Timesheet!$C$13:$C$11461,'Mês 1'!$G$40) -> 0 | V4: =SUMIFS(Timesheet!$F$13:$F$11461,Timesheet!$A$13:$A$11461,'Mês 1'!O4,Timesheet!$C$13:$C$11461,'Mês 1'!$V$3) -> 0 | W4: =SUMIFS(Timesheet!$F$13:$F$11461,Timesheet!$A$13:$A$11461,'Mês 1'!O4,Timesheet!$C$13:$C$11461,'Mês 1'!$W$3) -> 0 | X4: =SUMIFS(Timesheet!$F$13:$F$11461,Timesheet!$A$13:$A$11461,'Mês 1'!O4,Timesheet!$C$13:$C$11461,'Mês 1'!$X$3) -> 0 | Y4: =SUM(P4:W4) -> 0 | Z4: {=MIN(IF(Timesheet!$A$13:$A$11483='Mês 1'!O4,Timesheet!$D$13:$D$11483))} -> 0 | AA4: {=MAX(IF(Timesheet!$A$13:$A$11483='Mês 1'!O4,Timesheet!$E$13:$E$11483))} -> 0
A5: 44928 | B5: =SUMIFS(Timesheet!$F$13:$F$11461,Timesheet!$A$13:$A$11461,'Mês 1'!A5,Timesheet!$C$13:$C$11461,'Mês 1'!$B$40) -> 0 | C5: =SUMIFS(Timesheet!$F$13:$F$11461,Timesheet!$A$13:$A$11461,'Mês 1'!A5,Timesheet!$C$13:$C$11461,'Mês 1'!$C$40) -> 0 | D5: =SUMIFS(Timesheet!$F$13:$F$11461,Timesheet!$A$13:$A$11461,'Mês 1'!A5,Timesheet!$C$13:$C$11461,'Mês 1'!$D$40) -> 0 | E5: =SUMIFS(Timesheet!$F$13:$F$11461,Timesheet!$A$13:$A$11461,'Mês 1'!A5,Timesheet!$C$13:$C$11461,'Mês 1'!$E$40) -> 0 | F5: =SUMIFS(Timesheet!$F$13:$F$11461,Timesheet!$A$13:$A$11461,'Mês 1'!A5,Timesheet!$C$13:$C$11461,'Mês 1'!$F$40) -> 0 | G5: =SUMIFS(Timesheet!$F$13:$F$11461,Timesheet!$A$13:$A$11461,'Mês 1'!A5,Timesheet!$C$13:$C$11461,'Mês 1'!$G$40) -> 0 | H5: =SUMIFS(Timesheet!$F$13:$F$2615,Timesheet!$A$13:$A$2615,'Mês 1'!A5,Timesheet!$C$13:$C$2615,'Mês 1'!$H$3) -> 0 | I5: =SUMIFS(Timesheet!$F$13:$F$2615,Timesheet!$A$13:$A$2615,'Mês 1'!A5,Timesheet!$C$13:$C$2615,'Mês 1'!$I$3) -> 0 | J5: =SUMIFS(Timesheet!$F$13:$F$2615,Timesheet!$A$13:$A$2615,'Mês 1'!A5,Timesheet!$C$13:$C$2615,'Mês 1'!$J$3) -> 0 | K5: =SUM(B5:I5) -> 0 | L5: {=MIN(IF(Timesheet!$A$13:$A$11483='Mês 1'!A5,Timesheet!$D$13:$D$11483))} -> 0 | M5: {=MAX(IF(Timesheet!$A$13:$A$11483='Mês 1'!A5,Timesheet!$E$13:$E$11483))} -> 0 | O5: 44959 | P5: =SUMIFS(Timesheet!$F$13:$F$11461,Timesheet!$A$13:$A$11461,'Mês 1'!O5,Timesheet!$C$13:$C$11461,'Mês 1'!$B$40) -> 0 | Q5: =SUMIFS(Timesheet!$F$13:$F$11461,Timesheet!$A$13:$A$11461,'Mês 1'!O5,Timesheet!$C$13:$C$11461,'Mês 1'!$C$40) -> 0 | R5: =SUMIFS(Timesheet!$F$13:$F$11461,Timesheet!$A$13:$A$11461,'Mês 1'!O5,Timesheet!$C$13:$C$11461,'Mês 1'!$D$40) -> 0 | S5: =SUMIFS(Timesheet!$F$13:$F$11461,Timesheet!$A$13:$A$11461,'Mês 1'!O5,Timesheet!$C$13:$C$11461,'Mês 1'!$E$40) -> 0 | T5: =SUMIFS(Timesheet!$F$13:$F$11461,Timesheet!$A$13:$A$11461,'Mês 1'!O5,Timesheet!$C$13:$C$11461,'Mês 1'!$F$40) -> 0 | U5: =SUMIFS(Timesheet!$F$13:$F$11461,Timesheet!$A$13:$A$11461,'Mês 1'!O5,Timesheet!$C$13:$C$11461,'Mês 1'!$G$40) -> 0 | V5: =SUMIFS(Timesheet!$F$13:$F$11461,Timesheet!$A$13:$A$11461,'Mês 1'!O5,Timesheet!$C$13:$C$11461,'Mês 1'!$V$3) -> 0 | W5: =SUMIFS(Timesheet!$F$13:$F$11461,Timesheet!$A$13:$A$11461,'Mês 1'!O5,Timesheet!$C$13:$C$11461,'Mês 1'!$W$3) -> 0 | X5: =SUMIFS(Timesheet!$F$13:$F$11461,Timesheet!$A$13:$A$11461,'Mês 1'!O5,Timesheet!$C$13:$C$11461,'Mês 1'!$X$3) -> 0 | Y5: =SUM(P5:W5) -> 0 | Z5: {=MIN(IF(Timesheet!$A$13:$A$11483='Mês 1'!O5,Timesheet!$D$13:$D$11483))} -> 0 | AA5: {=MAX(IF(Timesheet!$A$13:$A$11483='Mês 1'!O5,Timesheet!$E$13:$E$11483))} -> 0
A6: 44929 | B6: =SUMIFS(Timesheet!$F$13:$F$11461,Timesheet!$A$13:$A$11461,'Mês 1'!A6,Timesheet!$C$13:$C$11461,'Mês 1'!$B$40) -> 0 | C6: =SUMIFS(Timesheet!$F$13:$F$11461,Timesheet!$A$13:$A$11461,'Mês 1'!A6,Timesheet!$C$13:$C$11461,'Mês 1'!$C$40) -> 0 | D6: =SUMIFS(Timesheet!$F$13:$F$11461,Timesheet!$A$13:$A$11461,'Mês 1'!A6,Timesheet!$C$13:$C$11461,'Mês 1'!$D$40) -> 0 | E6: =SUMIFS(Timesheet!$F$13:$F$11461,Timesheet!$A$13:$A$11461,'Mês 1'!A6,Timesheet!$C$13:$C$11461,'Mês 1'!$E$40) -> 0 | F6: =SUMIFS(Timesheet!$F$13:$F$11461,Timesheet!$A$13:$A$11461,'Mês 1'!A6,Timesheet!$C$13:$C$11461,'Mês 1'!$F$40) -> 0 | G6: =SUMIFS(Timesheet!$F$13:$F$11461,Timesheet!$A$13:$A$11461,'Mês 1'!A6,Timesheet!$C$13:$C$11461,'Mês 1'!$G$40) -> 0 | H6: =SUMIFS(Timesheet!$F$13:$F$2615,Timesheet!$A$13:$A$2615,'Mês 1'!A6,Timesheet!$C$13:$C$2615,'Mês 1'!$H$3) -> 0 | I6: =SUMIFS(Timesheet!$F$13:$F$2615,Timesheet!$A$13:$A$2615,'Mês 1'!A6,Timesheet!$C$13:$C$2615,'Mês 1'!$I$3) -> 0 | J6: =SUMIFS(Timesheet!$F$13:$F$2615,Timesheet!$A$13:$A$2615,'Mês 1'!A6,Timesheet!$C$13:$C$2615,'Mês 1'!$J$3) -> 0 | K6: =SUM(B6:I6) -> 0 | L6: {=MIN(IF(Timesheet!$A$13:$A$11483='Mês 1'!A6,Timesheet!$D$13:$D$11483))} -> 0 | M6: {=MAX(IF(Timesheet!$A$13:$A$11483='Mês 1'!A6,Timesheet!$E$13:$E$11483))} -> 0 | O6: 44960 | P6: =SUMIFS(Timesheet!$F$13:$F$11461,Timesheet!$A$13:$A$11461,'Mês 1'!O6,Timesheet!$C$13:$C$11461,'Mês 1'!$B$40) -> 0 | Q6: =SUMIFS(Timesheet!$F$13:$F$11461,Timesheet!$A$13:$A$11461,'Mês 1'!O6,Timesheet!$C$13:$C$11461,'Mês 1'!$C$40) -> 0 | R6: =SUMIFS(Timesheet!$F$13:$F$11461,Timesheet!$A$13:$A$11461,'Mês 1'!O6,Timesheet!$C$13:$C$11461,'Mês 1'!$D$40) -> 0 | S6: =SUMIFS(Timesheet!$F$13:$F$11461,Timesheet!$A$13:$A$11461,'Mês 1'!O6,Timesheet!$C$13:$C$11461,'Mês 1'!$E$40) -> 0 | T6: =SUMIFS(Timesheet!$F$13:$F$11461,Timesheet!$A$13:$A$11461,'Mês 1'!O6,Timesheet!$C$13:$C$11461,'Mês 1'!$F$40) -> 0 | U6: =SUMIFS(Timesheet!$F$13:$F$11461,Timesheet!$A$13:$A$11461,'Mês 1'!O6,Timesheet!$C$13:$C$11461,'Mês 1'!$G$40) -> 0 | V6: =SUMIFS(Timesheet!$F$13:$F$11461,Timesheet!$A$13:$A$11461,'Mês 1'!O6,Timesheet!$C$13:$C$11461,'Mês 1'!$V$3) -> 0 | W6: =SUMIFS(Timesheet!$F$13:$F$11461,Timesheet!$A$13:$A$11461,'Mês 1'!O6,Timesheet!$C$13:$C$11461,'Mês 1'!$W$3) -> 0 | X6: =SUMIFS(Timesheet!$F$13:$F$11461,Timesheet!$A$13:$A$11461,'Mês 1'!O6,Timesheet!$C$13:$C$11461,'Mês 1'!$X$3) -> 0 | Y6: =SUM(P6:W6) -> 0 | Z6: {=MIN(IF(Timesheet!$A$13:$A$11483='Mês 1'!O6,Timesheet!$D$13:$D$11483))} -> 0 | AA6: {=MAX(IF(Timesheet!$A$13:$A$11483='Mês 1'!O6,Timesheet!$E$13:$E$11483))} -> 0
A7: 44930 | B7: =SUMIFS(Timesheet!$F$13:$F$11461,Timesheet!$A$13:$A$11461,'Mês 1'!A7,Timesheet!$C$13:$C$11461,'Mês 1'!$B$40) -> 0 | C7: =SUMIFS(Timesheet!$F$13:$F$11461,Timesheet!$A$13:$A$11461,'Mês 1'!A7,Timesheet!$C$13:$C$11461,'Mês 1'!$C$40) -> 0 | D7: =SUMIFS(Timesheet!$F$13:$F$11461,Timesheet!$A$13:$A$11461,'Mês 1'!A7,Timesheet!$C$13:$C$11461,'Mês 1'!$D$40) -> 0 | E7: =SUMIFS(Timesheet!$F$13:$F$11461,Timesheet!$A$13:$A$11461,'Mês 1'!A7,Timesheet!$C$13:$C$11461,'Mês 1'!$E$40) -> 0 | F7: =SUMIFS(Timesheet!$F$13:$F$11461,Timesheet!$A$13:$A$11461,'Mês 1'!A7,Timesheet!$C$13:$C$11461,'Mês 1'!$F$40) -> 0 | G7: =SUMIFS(Timesheet!$F$13:$F$11461,Timesheet!$A$13:$A$11461,'Mês 1'!A7,Timesheet!$C$13:$C$11461,'Mês 1'!$G$40) -> 0 | H7: =SUMIFS(Timesheet!$F$13:$F$2615,Timesheet!$A$13:$A$2615,'Mês 1'!A7,Timesheet!$C$13:$C$2615,'Mês 1'!$H$3) -> 0 | I7: =SUMIFS(Timesheet!$F$13:$F$2615,Timesheet!$A$13:$A$2615,'Mês 1'!A7,Timesheet!$C$13:$C$2615,'Mês 1'!$I$3) -> 0 | J7: =SUMIFS(Timesheet!$F$13:$F$2615,Timesheet!$A$13:$A$2615,'Mês 1'!A7,Timesheet!$C$13:$C$2615,'Mês 1'!$J$3) -> 0 | K7: =SUM(B7:I7) -> 0 | L7: {=MIN(IF(Timesheet!$A$13:$A$11483='Mês 1'!A7,Timesheet!$D$13:$D$11483))} -> 0 | M7: {=MAX(IF(Timesheet!$A$13:$A$11483='Mês 1'!A7,Timesheet!$E$13:$E$11483))} -> 0 | O7: 44961 | P7: =SUMIFS(Timesheet!$F$13:$F$11461,Timesheet!$A$13:$A$11461,'Mês 1'!O7,Timesheet!$C$13:$C$11461,'Mês 1'!$B$40) -> 0 | Q7: =SUMIFS(Timesheet!$F$13:$F$11461,Timesheet!$A$13:$A$11461,'Mês 1'!O7,Timesheet!$C$13:$C$11461,'Mês 1'!$C$40) -> 0 | R7: =SUMIFS(Timesheet!$F$13:$F$11461,Timesheet!$A$13:$A$11461,'Mês 1'!O7,Timesheet!$C$13:$C$11461,'Mês 1'!$D$40) -> 0 | S7: =SUMIFS(Timesheet!$F$13:$F$11461,Timesheet!$A$13:$A$11461,'Mês 1'!O7,Timesheet!$C$13:$C$11461,'Mês 1'!$E$40) -> 0 | T7: =SUMIFS(Timesheet!$F$13:$F$11461,Timesheet!$A$13:$A$11461,'Mês 1'!O7,Timesheet!$C$13:$C$11461,'Mês 1'!$F$40) -> 0 | U7: =SUMIFS(Timesheet!$F$13:$F$11461,Timesheet!$A$13:$A$11461,'Mês 1'!O7,Timesheet!$C$13:$C$11461,'Mês 1'!$G$40) -> 0 | V7: =SUMIFS(Timesheet!$F$13:$F$11461,Timesheet!$A$13:$A$11461,'Mês 1'!O7,Timesheet!$C$13:$C$11461,'Mês 1'!$V$3) -> 0 | W7: =SUMIFS(Timesheet!$F$13:$F$11461,Timesheet!$A$13:$A$11461,'Mês 1'!O7,Timesheet!$C$13:$C$11461,'Mês 1'!$W$3) -> 0 | X7: =SUMIFS(Timesheet!$F$13:$F$11461,Timesheet!$A$13:$A$11461,'Mês 1'!O7,Timesheet!$C$13:$C$11461,'Mês 1'!$X$3) -> 0 | Y7: =SUM(P7:W7) -> 0 | Z7: {=MIN(IF(Timesheet!$A$13:$A$11483='Mês 1'!O7,Timesheet!$D$13:$D$11483))} -> 0 | AA7: {=MAX(IF(Timesheet!$A$13:$A$11483='Mês 1'!O7,Timesheet!$E$13:$E$11483))} -> 0
A8: 44931 | B8: =SUMIFS(Timesheet!$F$13:$F$11461,Timesheet!$A$13:$A$11461,'Mês 1'!A8,Timesheet!$C$13:$C$11461,'Mês 1'!$B$40) -> 0 | C8: =SUMIFS(Timesheet!$F$13:$F$11461,Timesheet!$A$13:$A$11461,'Mês 1'!A8,Timesheet!$C$13:$C$11461,'Mês 1'!$C$40) -> 0 | D8: =SUMIFS(Timesheet!$F$13:$F$11461,Timesheet!$A$13:$A$11461,'Mês 1'!A8,Timesheet!$C$13:$C$11461,'Mês 1'!$D$40) -> 0 | E8: =SUMIFS(Timesheet!$F$13:$F$11461,Timesheet!$A$13:$A$11461,'Mês 1'!A8,Timesheet!$C$13:$C$11461,'Mês 1'!$E$40) -> 0 | F8: =SUMIFS(Timesheet!$F$13:$F$11461,Timesheet!$A$13:$A$11461,'Mês 1'!A8,Timesheet!$C$13:$C$11461,'Mês 1'!$F$40) -> 0 | G8: =SUMIFS(Timesheet!$F$13:$F$11461,Timesheet!$A$13:$A$11461,'Mês 1'!A8,Timesheet!$C$13:$C$11461,'Mês 1'!$G$40) -> 0 | H8: =SUMIFS(Timesheet!$F$13:$F$2615,Timesheet!$A$13:$A$2615,'Mês 1'!A8,Timesheet!$C$13:$C$2615,'Mês 1'!$H$3) -> 0 | I8: =SUMIFS(Timesheet!$F$13:$F$2615,Timesheet!$A$13:$A$2615,'Mês 1'!A8,Timesheet!$C$13:$C$2615,'Mês 1'!$I$3) -> 0 | J8: =SUMIFS(Timesheet!$F$13:$F$2615,Timesheet!$A$13:$A$2615,'Mês 1'!A8,Timesheet!$C$13:$C$2615,'Mês 1'!$J$3) -> 0 | K8: =SUM(B8:I8) -> 0 | L8: {=MIN(IF(Timesheet!$A$13:$A$11483='Mês 1'!A8,Timesheet!$D$13:$D$11483))} -> 0 | M8: {=MAX(IF(Timesheet!$A$13:$A$11483='Mês 1'!A8,Timesheet!$E$13:$E$11483))} -> 0 | O8: 44962 | P8: =SUMIFS(Timesheet!$F$13:$F$11461,Timesheet!$A$13:$A$11461,'Mês 1'!O8,Timesheet!$C$13:$C$11461,'Mês 1'!$B$40) -> 0 | Q8: =SUMIFS(Timesheet!$F$13:$F$11461,Timesheet!$A$13:$A$11461,'Mês 1'!O8,Timesheet!$C$13:$C$11461,'Mês 1'!$C$40) -> 0 | R8: =SUMIFS(Timesheet!$F$13:$F$11461,Timesheet!$A$13:$A$11461,'Mês 1'!O8,Timesheet!$C$13:$C$11461,'Mês 1'!$D$40) -> 0 | S8: =SUMIFS(Timesheet!$F$13:$F$11461,Timesheet!$A$13:$A$11461,'Mês 1'!O8,Timesheet!$C$13:$C$11461,'Mês 1'!$E$40) -> 0 | T8: =SUMIFS(Timesheet!$F$13:$F$11461,Timesheet!$A$13:$A$11461,'Mês 1'!O8,Timesheet!$C$13:$C$11461,'Mês 1'!$F$40) -> 0 | U8: =SUMIFS(Timesheet!$F$13:$F$11461,Timesheet!$A$13:$A$11461,'Mês 1'!O8,Timesheet!$C$13:$C$11461,'Mês 1'!$G$40) -> 0 | V8: =SUMIFS(Timesheet!$F$13:$F$11461,Timesheet!$A$13:$A$11461,'Mês 1'!O8,Timesheet!$C$13:$C$11461,'Mês 1'!$V$3) -> 0 | W8: =SUMIFS(Timesheet!$F$13:$F$11461,Timesheet!$A$13:$A$11461,'Mês 1'!O8,Timesheet!$C$13:$C$11461,'Mês 1'!$W$3) -> 0 | X8: =SUMIFS(Timesheet!$F$13:$F$11461,Timesheet!$A$13:$A$11461,'Mês 1'!O8,Timesheet!$C$13:$C$11461,'Mês 1'!$X$3) -> 0 | Y8: =SUM(P8:W8) -> 0 | Z8: {=MIN(IF(Timesheet!$A$13:$A$11483='Mês 1'!O8,Timesheet!$D$13:$D$11483))} -> 0 | AA8: {=MAX(IF(Timesheet!$A$13:$A$11483='Mês 1'!O8,Timesheet!$E$13:$E$11483))} -> 0
A9: 44932 | B9: =SUMIFS(Timesheet!$F$13:$F$11461,Timesheet!$A$13:$A$11461,'Mês 1'!A9,Timesheet!$C$13:$C$11461,'Mês 1'!$B$40) -> 0 | C9: =SUMIFS(Timesheet!$F$13:$F$11461,Timesheet!$A$13:$A$11461,'Mês 1'!A9,Timesheet!$C$13:$C$11461,'Mês 1'!$C$40) -> 0 | D9: =SUMIFS(Timesheet!$F$13:$F$11461,Timesheet!$A$13:$A$11461,'Mês 1'!A9,Timesheet!$C$13:$C$11461,'Mês 1'!$D$40) -> 0 | E9: =SUMIFS(Timesheet!$F$13:$F$11461,Timesheet!$A$13:$A$11461,'Mês 1'!A9,Timesheet!$C$13:$C$11461,'Mês 1'!$E$40) -> 0 | F9: =SUMIFS(Timesheet!$F$13:$F$11461,Timesheet!$A$13:$A$11461,'Mês 1'!A9,Timesheet!$C$13:$C$11461,'Mês 1'!$F$40) -> 0 | G9: =SUMIFS(Timesheet!$F$13:$F$11461,Timesheet!$A$13:$A$11461,'Mês 1'!A9,Timesheet!$C$13:$C$11461,'Mês 1'!$G$40) -> 0 | H9: =SUMIFS(Timesheet!$F$13:$F$2615,Timesheet!$A$13:$A$2615,'Mês 1'!A9,Timesheet!$C$13:$C$2615,'Mês 1'!$H$3) -> 0 | I9: =SUMIFS(Timesheet!$F$13:$F$2615,Timesheet!$A$13:$A$2615,'Mês 1'!A9,Timesheet!$C$13:$C$2615,'Mês 1'!$I$3) -> 0 | J9: =SUMIFS(Timesheet!$F$13:$F$2615,Timesheet!$A$13:$A$2615,'Mês 1'!A9,Timesheet!$C$13:$C$2615,'Mês 1'!$J$3) -> 0 | K9: =SUM(B9:I9) -> 0 | L9: {=MIN(IF(Timesheet!$A$13:$A$11483='Mês 1'!A9,Timesheet!$D$13:$D$11483))} -> 0 | M9: {=MAX(IF(Timesheet!$A$13:$A$11483='Mês 1'!A9,Timesheet!$E$13:$E$11483))} -> 0 | O9: 44963 | P9: =SUMIFS(Timesheet!$F$13:$F$11461,Timesheet!$A$13:$A$11461,'Mês 1'!O9,Timesheet!$C$13:$C$11461,'Mês 1'!$B$40) -> 0 | Q9: =SUMIFS(Timesheet!$F$13:$F$11461,Timesheet!$A$13:$A$11461,'Mês 1'!O9,Timesheet!$C$13:$C$11461,'Mês 1'!$C$40) -> 0 | R9: =SUMIFS(Timesheet!$F$13:$F$11461,Timesheet!$A$13:$A$11461,'Mês 1'!O9,Timesheet!$C$13:$C$11461,'Mês 1'!$D$40) -> 0 | S9: =SUMIFS(Timesheet!$F$13:$F$11461,Timesheet!$A$13:$A$11461,'Mês 1'!O9,Timesheet!$C$13:$C$11461,'Mês 1'!$E$40) -> 0 | T9: =SUMIFS(Timesheet!$F$13:$F$11461,Timesheet!$A$13:$A$11461,'Mês 1'!O9,Timesheet!$C$13:$C$11461,'Mês 1'!$F$40) -> 0 | U9: =SUMIFS(Timesheet!$F$13:$F$11461,Timesheet!$A$13:$A$11461,'Mês 1'!O9,Timesheet!$C$13:$C$11461,'Mês 1'!$G$40) -> 0 | V9: =SUMIFS(Timesheet!$F$13:$F$11461,Timesheet!$A$13:$A$11461,'Mês 1'!O9,Timesheet!$C$13:$C$11461,'Mês 1'!$V$3) -> 0 | W9: =SUMIFS(Timesheet!$F$13:$F$11461,Timesheet!$A$13:$A$11461,'Mês 1'!O9,Timesheet!$C$13:$C$11461,'Mês 1'!$W$3) -> 0 | X9: =SUMIFS(Timesheet!$F$13:$F$11461,Timesheet!$A$13:$A$11461,'Mês 1'!O9,Timesheet!$C$13:$C$11461,'Mês 1'!$X$3) -> 0 | Y9: =SUM(P9:W9) -> 0 | Z9: {=MIN(IF(Timesheet!$A$13:$A$11483='Mês 1'!O9,Timesheet!$D$13:$D$11483))} -> 0 | AA9: {=MAX(IF(Timesheet!$A$13:$A$11483='Mês 1'!O9,Timesheet!$E$13:$E$11483))} -> 0
A10: 44933 | B10: =SUMIFS(Timesheet!$F$13:$F$11461,Timesheet!$A$13:$A$11461,'Mês 1'!A10,Timesheet!$C$13:$C$11461,'Mês 1'!$B$40) -> 0 | C10: =SUMIFS(Timesheet!$F$13:$F$11461,Timesheet!$A$13:$A$11461,'Mês 1'!A10,Timesheet!$C$13:$C$11461,'Mês 1'!$C$40) -> 0 | D10: =SUMIFS(Timesheet!$F$13:$F$11461,Timesheet!$A$13:$A$11461,'Mês 1'!A10,Timesheet!$C$13:$C$11461,'Mês 1'!$D$40) -> 0 | E10: =SUMIFS(Timesheet!$F$13:$F$11461,Timesheet!$A$13:$A$11461,'Mês 1'!A10,Timesheet!$C$13:$C$11461,'Mês 1'!$E$40) -> 0 | F10: =SUMIFS(Timesheet!$F$13:$F$11461,Timesheet!$A$13:$A$11461,'Mês 1'!A10,Timesheet!$C$13:$C$11461,'Mês 1'!$F$40) -> 0 | G10: =SUMIFS(Timesheet!$F$13:$F$11461,Timesheet!$A$13:$A$11461,'Mês 1'!A10,Timesheet!$C$13:$C$11461,'Mês 1'!$G$40) -> 0 | H10: =SUMIFS(Timesheet!$F$13:$F$2615,Timesheet!$A$13:$A$2615,'Mês 1'!A10,Timesheet!$C$13:$C$2615,'Mês 1'!$H$3) -> 0 | I10: =SUMIFS(Timesheet!$F$13:$F$2615,Timesheet!$A$13:$A$2615,'Mês 1'!A10,Timesheet!$C$13:$C$2615,'Mês 1'!$I$3) -> 0 | J10: =SUMIFS(Timesheet!$F$13:$F$2615,Timesheet!$A$13:$A$2615,'Mês 1'!A10,Timesheet!$C$13:$C$2615,'Mês 1'!$J$3) -> 0 | K10: =SUM(B10:I10) -> 0 | L10: {=MIN(IF(Timesheet!$A$13:$A$11483='Mês 1'!A10,Timesheet!$D$13:$D$11483))} -> 0 | M10: {=MAX(IF(Timesheet!$A$13:$A$11483='Mês 1'!A10,Timesheet!$E$13:$E$11483))} -> 0 | O10: 44964 | P10: =SUMIFS(Timesheet!$F$13:$F$11461,Timesheet!$A$13:$A$11461,'Mês 1'!O10,Timesheet!$C$13:$C$11461,'Mês 1'!$B$40) -> 0 | Q10: =SUMIFS(Timesheet!$F$13:$F$11461,Timesheet!$A$13:$A$11461,'Mês 1'!O10,Timesheet!$C$13:$C$11461,'Mês 1'!$C$40) -> 0 | R10: =SUMIFS(Timesheet!$F$13:$F$11461,Timesheet!$A$13:$A$11461,'Mês 1'!O10,Timesheet!$C$13:$C$11461,'Mês 1'!$D$40) -> 0 | S10: =SUMIFS(Timesheet!$F$13:$F$11461,Timesheet!$A$13:$A$11461,'Mês 1'!O10,Timesheet!$C$13:$C$11461,'Mês 1'!$E$40) -> 0 | T10: =SUMIFS(Timesheet!$F$13:$F$11461,Timesheet!$A$13:$A$11461,'Mês 1'!O10,Timesheet!$C$13:$C$11461,'Mês 1'!$F$40) -> 0 | U10: =SUMIFS(Timesheet!$F$13:$F$11461,Timesheet!$A$13:$A$11461,'Mês 1'!O10,Timesheet!$C$13:$C$11461,'Mês 1'!$G$40) -> 0 | V10: =SUMIFS(Timesheet!$F$13:$F$11461,Timesheet!$A$13:$A$11461,'Mês 1'!O10,Timesheet!$C$13:$C$11461,'Mês 1'!$V$3) -> 0 | W10: =SUMIFS(Timesheet!$F$13:$F$11461,Timesheet!$A$13:$A$11461,'Mês 1'!O10,Timesheet!$C$13:$C$11461,'Mês 1'!$W$3) -> 0 | X10: =SUMIFS(Timesheet!$F$13:$F$11461,Timesheet!$A$13:$A$11461,'Mês 1'!O10,Timesheet!$C$13:$C$11461,'Mês 1'!$X$3) -> 0 | Y10: =SUM(P10:W10) -> 0 | Z10: {=MIN(IF(Timesheet!$A$13:$A$11483='Mês 1'!O10,Timesheet!$D$13:$D$11483))} -> 0 | AA10: {=MAX(IF(Timesheet!$A$13:$A$11483='Mês 1'!O10,Timesheet!$E$13:$E$11483))} -> 0
A11: 44934 | B11: =SUMIFS(Timesheet!$F$13:$F$11461,Timesheet!$A$13:$A$11461,'Mês 1'!A11,Timesheet!$C$13:$C$11461,'Mês 1'!$B$40) -> 0 | C11: =SUMIFS(Timesheet!$F$13:$F$11461,Timesheet!$A$13:$A$11461,'Mês 1'!A11,Timesheet!$C$13:$C$11461,'Mês 1'!$C$40) -> 0 | D11: =SUMIFS(Timesheet!$F$13:$F$11461,Timesheet!$A$13:$A$11461,'Mês 1'!A11,Timesheet!$C$13:$C$11461,'Mês 1'!$D$40) -> 0 | E11: =SUMIFS(Timesheet!$F$13:$F$11461,Timesheet!$A$13:$A$11461,'Mês 1'!A11,Timesheet!$C$13:$C$11461,'Mês 1'!$E$40) -> 0 | F11: =SUMIFS(Timesheet!$F$13:$F$11461,Timesheet!$A$13:$A$11461,'Mês 1'!A11,Timesheet!$C$13:$C$11461,'Mês 1'!$F$40) -> 0 | G11: =SUMIFS(Timesheet!$F$13:$F$11461,Timesheet!$A$13:$A$11461,'Mês 1'!A11,Timesheet!$C$13:$C$11461,'Mês 1'!$G$40) -> 0 | H11: =SUMIFS(Timesheet!$F$13:$F$2615,Timesheet!$A$13:$A$2615,'Mês 1'!A11,Timesheet!$C$13:$C$2615,'Mês 1'!$H$3) -> 0 | I11: =SUMIFS(Timesheet!$F$13:$F$2615,Timesheet!$A$13:$A$2615,'Mês 1'!A11,Timesheet!$C$13:$C$2615,'Mês 1'!$I$3) -> 0 | J11: =SUMIFS(Timesheet!$F$13:$F$2615,Timesheet!$A$13:$A$2615,'Mês 1'!A11,Timesheet!$C$13:$C$2615,'Mês 1'!$J$3) -> 0 | K11: =SUM(B11:I11) -> 0 | L11: {=MIN(IF(Timesheet!$A$13:$A$11483='Mês 1'!A11,Timesheet!$D$13:$D$11483))} -> 0 | M11: {=MAX(IF(Timesheet!$A$13:$A$11483='Mês 1'!A11,Timesheet!$E$13:$E$11483))} -> 0 | O11: 44965 | P11: =SUMIFS(Timesheet!$F$13:$F$11461,Timesheet!$A$13:$A$11461,'Mês 1'!O11,Timesheet!$C$13:$C$11461,'Mês 1'!$B$40) -> 0 | Q11: =SUMIFS(Timesheet!$F$13:$F$11461,Timesheet!$A$13:$A$11461,'Mês 1'!O11,Timesheet!$C$13:$C$11461,'Mês 1'!$C$40) -> 0 | R11: =SUMIFS(Timesheet!$F$13:$F$11461,Timesheet!$A$13:$A$11461,'Mês 1'!O11,Timesheet!$C$13:$C$11461,'Mês 1'!$D$40) -> 0 | S11: =SUMIFS(Timesheet!$F$13:$F$11461,Timesheet!$A$13:$A$11461,'Mês 1'!O11,Timesheet!$C$13:$C$11461,'Mês 1'!$E$40) -> 0 | T11: =SUMIFS(Timesheet!$F$13:$F$11461,Timesheet!$A$13:$A$11461,'Mês 1'!O11,Timesheet!$C$13:$C$11461,'Mês 1'!$F$40) -> 0 | U11: =SUMIFS(Timesheet!$F$13:$F$11461,Timesheet!$A$13:$A$11461,'Mês 1'!O11,Timesheet!$C$13:$C$11461,'Mês 1'!$G$40) -> 0 | V11: =SUMIFS(Timesheet!$F$13:$F$11461,Timesheet!$A$13:$A$11461,'Mês 1'!O11,Timesheet!$C$13:$C$11461,'Mês 1'!$V$3) -> 0 | W11: =SUMIFS(Timesheet!$F$13:$F$11461,Timesheet!$A$13:$A$11461,'Mês 1'!O11,Timesheet!$C$13:$C$11461,'Mês 1'!$W$3) -> 0 | X11: =SUMIFS(Timesheet!$F$13:$F$11461,Timesheet!$A$13:$A$11461,'Mês 1'!O11,Timesheet!$C$13:$C$11461,'Mês 1'!$X$3) -> 0 | Y11: =SUM(P11:W11) -> 0 | Z11: {=MIN(IF(Timesheet!$A$13:$A$11483='Mês 1'!O11,Timesheet!$D$13:$D$11483))} -> 0 | AA11: {=MAX(IF(Timesheet!$A$13:$A$11483='Mês 1'!O11,Timesheet!$E$13:$E$11483))} -> 0
A12: 44935 | B12: =SUMIFS(Timesheet!$F$13:$F$11461,Timesheet!$A$13:$A$11461,'Mês 1'!A12,Timesheet!$C$13:$C$11461,'Mês 1'!$B$40) -> 0 | C12: =SUMIFS(Timesheet!$F$13:$F$11461,Timesheet!$A$13:$A$11461,'Mês 1'!A12,Timesheet!$C$13:$C$11461,'Mês 1'!$C$40) -> 0 | D12: =SUMIFS(Timesheet!$F$13:$F$11461,Timesheet!$A$13:$A$11461,'Mês 1'!A12,Timesheet!$C$13:$C$11461,'Mês 1'!$D$40) -> 0 | E12: =SUMIFS(Timesheet!$F$13:$F$11461,Timesheet!$A$13:$A$11461,'Mês 1'!A12,Timesheet!$C$13:$C$11461,'Mês 1'!$E$40) -> 0 | F12: =SUMIFS(Timesheet!$F$13:$F$11461,Timesheet!$A$13:$A$11461,'Mês 1'!A12,Timesheet!$C$13:$C$11461,'Mês 1'!$F$40) -> 0 | G12: =SUMIFS(Timesheet!$F$13:$F$11461,Timesheet!$A$13:$A$11461,'Mês 1'!A12,Timesheet!$C$13:$C$11461,'Mês 1'!$G$40) -> 0 | H12: =SUMIFS(Timesheet!$F$13:$F$2615,Timesheet!$A$13:$A$2615,'Mês 1'!A12,Timesheet!$C$13:$C$2615,'Mês 1'!$H$3) -> 0 | I12: =SUMIFS(Timesheet!$F$13:$F$2615,Timesheet!$A$13:$A$2615,'Mês 1'!A12,Timesheet!$C$13:$C$2615,'Mês 1'!$I$3) -> 0 | J12: =SUMIFS(Timesheet!$F$13:$F$2615,Timesheet!$A$13:$A$2615,'Mês 1'!A12,Timesheet!$C$13:$C$2615,'Mês 1'!$J$3) -> 0 | K12: =SUM(B12:I12) -> 0 | L12: {=MIN(IF(Timesheet!$A$13:$A$11483='Mês 1'!A12,Timesheet!$D$13:$D$11483))} -> 0 | M12: {=MAX(IF(Timesheet!$A$13:$A$11483='Mês 1'!A12,Timesheet!$E$13:$E$11483))} -> 0 | O12: 44966 | P12: =SUMIFS(Timesheet!$F$13:$F$11461,Timesheet!$A$13:$A$11461,'Mês 1'!O12,Timesheet!$C$13:$C$11461,'Mês 1'!$B$40) -> 0 | Q12: =SUMIFS(Timesheet!$F$13:$F$11461,Timesheet!$A$13:$A$11461,'Mês 1'!O12,Timesheet!$C$13:$C$11461,'Mês 1'!$C$40) -> 0 | R12: =SUMIFS(Timesheet!$F$13:$F$11461,Timesheet!$A$13:$A$11461,'Mês 1'!O12,Timesheet!$C$13:$C$11461,'Mês 1'!$D$40) -> 0 | S12: =SUMIFS(Timesheet!$F$13:$F$11461,Timesheet!$A$13:$A$11461,'Mês 1'!O12,Timesheet!$C$13:$C$11461,'Mês 1'!$E$40) -> 0 | T12: =SUMIFS(Timesheet!$F$13:$F$11461,Timesheet!$A$13:$A$11461,'Mês 1'!O12,Timesheet!$C$13:$C$11461,'Mês 1'!$F$40) -> 0 | U12: =SUMIFS(Timesheet!$F$13:$F$11461,Timesheet!$A$13:$A$11461,'Mês 1'!O12,Timesheet!$C$13:$C$11461,'Mês 1'!$G$40) -> 0 | V12: =SUMIFS(Timesheet!$F$13:$F$11461,Timesheet!$A$13:$A$11461,'Mês 1'!O12,Timesheet!$C$13:$C$11461,'Mês 1'!$V$3) -> 0 | W12: =SUMIFS(Timesheet!$F$13:$F$11461,Timesheet!$A$13:$A$11461,'Mês 1'!O12,Timesheet!$C$13:$C$11461,'Mês 1'!$W$3) -> 0 | X12: =SUMIFS(Timesheet!$F$13:$F$11461,Timesheet!$A$13:$A$11461,'Mês 1'!O12,Timesheet!$C$13:$C$11461,'Mês 1'!$X$3) -> 0 | Y12: =SUM(P12:W12) -> 0 | Z12: {=MIN(IF(Timesheet!$A$13:$A$11483='Mês 1'!O12,Timesheet!$D$13:$D$11483))} -> 0 | AA12: {=MAX(IF(Timesheet!$A$13:$A$11483='Mês 1'!O12,Timesheet!$E$13:$E$11483))} -> 0
A13: 44936 | B13: =SUMIFS(Timesheet!$F$13:$F$11461,Timesheet!$A$13:$A$11461,'Mês 1'!A13,Timesheet!$C$13:$C$11461,'Mês 1'!$B$40) -> 0 | C13: =SUMIFS(Timesheet!$F$13:$F$11461,Timesheet!$A$13:$A$11461,'Mês 1'!A13,Timesheet!$C$13:$C$11461,'Mês 1'!$C$40) -> 0 | D13: =SUMIFS(Timesheet!$F$13:$F$11461,Timesheet!$A$13:$A$11461,'Mês 1'!A13,Timesheet!$C$13:$C$11461,'Mês 1'!$D$40) -> 0 | E13: =SUMIFS(Timesheet!$F$13:$F$11461,Timesheet!$A$13:$A$11461,'Mês 1'!A13,Timesheet!$C$13:$C$11461,'Mês 1'!$E$40) -> 0 | F13: =SUMIFS(Timesheet!$F$13:$F$11461,Timesheet!$A$13:$A$11461,'Mês 1'!A13,Timesheet!$C$13:$C$11461,'Mês 1'!$F$40) -> 0 | G13: =SUMIFS(Timesheet!$F$13:$F$11461,Timesheet!$A$13:$A$11461,'Mês 1'!A13,Timesheet!$C$13:$C$11461,'Mês 1'!$G$40) -> 0 | H13: =SUMIFS(Timesheet!$F$13:$F$2615,Timesheet!$A$13:$A$2615,'Mês 1'!A13,Timesheet!$C$13:$C$2615,'Mês 1'!$H$3) -> 0 | I13: =SUMIFS(Timesheet!$F$13:$F$2615,Timesheet!$A$13:$A$2615,'Mês 1'!A13,Timesheet!$C$13:$C$2615,'Mês 1'!$I$3) -> 0 | J13: =SUMIFS(Timesheet!$F$13:$F$2615,Timesheet!$A$13:$A$2615,'Mês 1'!A13,Timesheet!$C$13:$C$2615,'Mês 1'!$J$3) -> 0 | K13: =SUM(B13:I13) -> 0 | L13: {=MIN(IF(Timesheet!$A$13:$A$11483='Mês 1'!A13,Timesheet!$D$13:$D$11483))} -> 0 | M13: {=MAX(IF(Timesheet!$A$13:$A$11483='Mês 1'!A13,Timesheet!$E$13:$E$11483))} -> 0 | O13: 44967 | P13: =SUMIFS(Timesheet!$F$13:$F$11461,Timesheet!$A$13:$A$11461,'Mês 1'!O13,Timesheet!$C$13:$C$11461,'Mês 1'!$B$40) -> 0 | Q13: =SUMIFS(Timesheet!$F$13:$F$11461,Timesheet!$A$13:$A$11461,'Mês 1'!O13,Timesheet!$C$13:$C$11461,'Mês 1'!$C$40) -> 0 | R13: =SUMIFS(Timesheet!$F$13:$F$11461,Timesheet!$A$13:$A$11461,'Mês 1'!O13,Timesheet!$C$13:$C$11461,'Mês 1'!$D$40) -> 0 | S13: =SUMIFS(Timesheet!$F$13:$F$11461,Timesheet!$A$13:$A$11461,'Mês 1'!O13,Timesheet!$C$13:$C$11461,'Mês 1'!$E$40) -> 0 | T13: =SUMIFS(Timesheet!$F$13:$F$11461,Timesheet!$A$13:$A$11461,'Mês 1'!O13,Timesheet!$C$13:$C$11461,'Mês 1'!$F$40) -> 0 | U13: =SUMIFS(Timesheet!$F$13:$F$11461,Timesheet!$A$13:$A$11461,'Mês 1'!O13,Timesheet!$C$13:$C$11461,'Mês 1'!$G$40) -> 0 | V13: =SUMIFS(Timesheet!$F$13:$F$11461,Timesheet!$A$13:$A$11461,'Mês 1'!O13,Timesheet!$C$13:$C$11461,'Mês 1'!$V$3) -> 0 | W13: =SUMIFS(Timesheet!$F$13:$F$11461,Timesheet!$A$13:$A$11461,'Mês 1'!O13,Timesheet!$C$13:$C$11461,'Mês 1'!$W$3) -> 0 | X13: =SUMIFS(Timesheet!$F$13:$F$11461,Timesheet!$A$13:$A$11461,'Mês 1'!O13,Timesheet!$C$13:$C$11461,'Mês 1'!$X$3) -> 0 | Y13: =SUM(P13:W13) -> 0 | Z13: {=MIN(IF(Timesheet!$A$13:$A$11483='Mês 1'!O13,Timesheet!$D$13:$D$11483))} -> 0 | AA13: {=MAX(IF(Timesheet!$A$13:$A$11483='Mês 1'!O13,Timesheet!$E$13:$E$11483))} -> 0
A14: 44937 | B14: =SUMIFS(Timesheet!$F$13:$F$11461,Timesheet!$A$13:$A$11461,'Mês 1'!A14,Timesheet!$C$13:$C$11461,'Mês 1'!$B$40) -> 0 | C14: =SUMIFS(Timesheet!$F$13:$F$11461,Timesheet!$A$13:$A$11461,'Mês 1'!A14,Timesheet!$C$13:$C$11461,'Mês 1'!$C$40) -> 0 | D14: =SUMIFS(Timesheet!$F$13:$F$11461,Timesheet!$A$13:$A$11461,'Mês 1'!A14,Timesheet!$C$13:$C$11461,'Mês 1'!$D$40) -> 0 | E14: =SUMIFS(Timesheet!$F$13:$F$11461,Timesheet!$A$13:$A$11461,'Mês 1'!A14,Timesheet!$C$13:$C$11461,'Mês 1'!$E$40) -> 0 | F14: =SUMIFS(Timesheet!$F$13:$F$11461,Timesheet!$A$13:$A$11461,'Mês 1'!A14,Timesheet!$C$13:$C$11461,'Mês 1'!$F$40) -> 0 | G14: =SUMIFS(Timesheet!$F$13:$F$11461,Timesheet!$A$13:$A$11461,'Mês 1'!A14,Timesheet!$C$13:$C$11461,'Mês 1'!$G$40) -> 0 | H14: =SUMIFS(Timesheet!$F$13:$F$2615,Timesheet!$A$13:$A$2615,'Mês 1'!A14,Timesheet!$C$13:$C$2615,'Mês 1'!$H$3) -> 0 | I14: =SUMIFS(Timesheet!$F$13:$F$2615,Timesheet!$A$13:$A$2615,'Mês 1'!A14,Timesheet!$C$13:$C$2615,'Mês 1'!$I$3) -> 0 | J14: =SUMIFS(Timesheet!$F$13:$F$2615,Timesheet!$A$13:$A$2615,'Mês 1'!A14,Timesheet!$C$13:$C$2615,'Mês 1'!$J$3) -> 0 | K14: =SUM(B14:I14) -> 0 | L14: {=MIN(IF(Timesheet!$A$13:$A$11483='Mês 1'!A14,Timesheet!$D$13:$D$11483))} -> 0 | M14: {=MAX(IF(Timesheet!$A$13:$A$11483='Mês 1'!A14,Timesheet!$E$13:$E$11483))} -> 0 | O14: 44968 | P14: =SUMIFS(Timesheet!$F$13:$F$11461,Timesheet!$A$13:$A$11461,'Mês 1'!O14,Timesheet!$C$13:$C$11461,'Mês 1'!$B$40) -> 0 | Q14: =SUMIFS(Timesheet!$F$13:$F$11461,Timesheet!$A$13:$A$11461,'Mês 1'!O14,Timesheet!$C$13:$C$11461,'Mês 1'!$C$40) -> 0 | R14: =SUMIFS(Timesheet!$F$13:$F$11461,Timesheet!$A$13:$A$11461,'Mês 1'!O14,Timesheet!$C$13:$C$11461,'Mês 1'!$D$40) -> 0 | S14: =SUMIFS(Timesheet!$F$13:$F$11461,Timesheet!$A$13:$A$11461,'Mês 1'!O14,Timesheet!$C$13:$C$11461,'Mês 1'!$E$40) -> 0 | T14: =SUMIFS(Timesheet!$F$13:$F$11461,Timesheet!$A$13:$A$11461,'Mês 1'!O14,Timesheet!$C$13:$C$11461,'Mês 1'!$F$40) -> 0 | U14: =SUMIFS(Timesheet!$F$13:$F$11461,Timesheet!$A$13:$A$11461,'Mês 1'!O14,Timesheet!$C$13:$C$11461,'Mês 1'!$G$40) -> 0 | V14: =SUMIFS(Timesheet!$F$13:$F$11461,Timesheet!$A$13:$A$11461,'Mês 1'!O14,Timesheet!$C$13:$C$11461,'Mês 1'!$V$3) -> 0 | W14: =SUMIFS(Timesheet!$F$13:$F$11461,Timesheet!$A$13:$A$11461,'Mês 1'!O14,Timesheet!$C$13:$C$11461,'Mês 1'!$W$3) -> 0 | X14: =SUMIFS(Timesheet!$F$13:$F$11461,Timesheet!$A$13:$A$11461,'Mês 1'!O14,Timesheet!$C$13:$C$11461,'Mês 1'!$X$3) -> 0 | Y14: =SUM(P14:W14) -> 0 | Z14: {=MIN(IF(Timesheet!$A$13:$A$11483='Mês 1'!O14,Timesheet!$D$13:$D$11483))} -> 0 | AA14: {=MAX(IF(Timesheet!$A$13:$A$11483='Mês 1'!O14,Timesheet!$E$13:$E$11483))} -> 0
A15: 44938 | B15: =SUMIFS(Timesheet!$F$13:$F$11461,Timesheet!$A$13:$A$11461,'Mês 1'!A15,Timesheet!$C$13:$C$11461,'Mês 1'!$B$40) -> 0 | C15: =SUMIFS(Timesheet!$F$13:$F$11461,Timesheet!$A$13:$A$11461,'Mês 1'!A15,Timesheet!$C$13:$C$11461,'Mês 1'!$C$40) -> 0 | D15: =SUMIFS(Timesheet!$F$13:$F$11461,Timesheet!$A$13:$A$11461,'Mês 1'!A15,Timesheet!$C$13:$C$11461,'Mês 1'!$D$40) -> 0 | E15: =SUMIFS(Timesheet!$F$13:$F$11461,Timesheet!$A$13:$A$11461,'Mês 1'!A15,Timesheet!$C$13:$C$11461,'Mês 1'!$E$40) -> 0 | F15: =SUMIFS(Timesheet!$F$13:$F$11461,Timesheet!$A$13:$A$11461,'Mês 1'!A15,Timesheet!$C$13:$C$11461,'Mês 1'!$F$40) -> 0 | G15: =SUMIFS(Timesheet!$F$13:$F$11461,Timesheet!$A$13:$A$11461,'Mês 1'!A15,Timesheet!$C$13:$C$11461,'Mês 1'!$G$40) -> 0 | H15: =SUMIFS(Timesheet!$F$13:$F$2615,Timesheet!$A$13:$A$2615,'Mês 1'!A15,Timesheet!$C$13:$C$2615,'Mês 1'!$H$3) -> 0 | I15: =SUMIFS(Timesheet!$F$13:$F$2615,Timesheet!$A$13:$A$2615,'Mês 1'!A15,Timesheet!$C$13:$C$2615,'Mês 1'!$I$3) -> 0 | J15: =SUMIFS(Timesheet!$F$13:$F$2615,Timesheet!$A$13:$A$2615,'Mês 1'!A15,Timesheet!$C$13:$C$2615,'Mês 1'!$J$3) -> 0 | K15: =SUM(B15:I15) -> 0 | L15: {=MIN(IF(Timesheet!$A$13:$A$11483='Mês 1'!A15,Timesheet!$D$13:$D$11483))} -> 0 | M15: {=MAX(IF(Timesheet!$A$13:$A$11483='Mês 1'!A15,Timesheet!$E$13:$E$11483))} -> 0 | O15: 44969 | P15: =SUMIFS(Timesheet!$F$13:$F$11461,Timesheet!$A$13:$A$11461,'Mês 1'!O15,Timesheet!$C$13:$C$11461,'Mês 1'!$B$40) -> 0 | Q15: =SUMIFS(Timesheet!$F$13:$F$11461,Timesheet!$A$13:$A$11461,'Mês 1'!O15,Timesheet!$C$13:$C$11461,'Mês 1'!$C$40) -> 0 | R15: =SUMIFS(Timesheet!$F$13:$F$11461,Timesheet!$A$13:$A$11461,'Mês 1'!O15,Timesheet!$C$13:$C$11461,'Mês 1'!$D$40) -> 0 | S15: =SUMIFS(Timesheet!$F$13:$F$11461,Timesheet!$A$13:$A$11461,'Mês 1'!O15,Timesheet!$C$13:$C$11461,'Mês 1'!$E$40) -> 0 | T15: =SUMIFS(Timesheet!$F$13:$F$11461,Timesheet!$A$13:$A$11461,'Mês 1'!O15,Timesheet!$C$13:$C$11461,'Mês 1'!$F$40) -> 0 | U15: =SUMIFS(Timesheet!$F$13:$F$11461,Timesheet!$A$13:$A$11461,'Mês 1'!O15,Timesheet!$C$13:$C$11461,'Mês 1'!$G$40) -> 0 | V15: =SUMIFS(Timesheet!$F$13:$F$11461,Timesheet!$A$13:$A$11461,'Mês 1'!O15,Timesheet!$C$13:$C$11461,'Mês 1'!$V$3) -> 0 | W15: =SUMIFS(Timesheet!$F$13:$F$11461,Timesheet!$A$13:$A$11461,'Mês 1'!O15,Timesheet!$C$13:$C$11461,'Mês 1'!$W$3) -> 0 | X15: =SUMIFS(Timesheet!$F$13:$F$11461,Timesheet!$A$13:$A$11461,'Mês 1'!O15,Timesheet!$C$13:$C$11461,'Mês 1'!$X$3) -> 0 | Y15: =SUM(P15:W15) -> 0 | Z15: {=MIN(IF(Timesheet!$A$13:$A$11483='Mês 1'!O15,Timesheet!$D$13:$D$11483))} -> 0 | AA15: {=MAX(IF(Timesheet!$A$13:$A$11483='Mês 1'!O15,Timesheet!$E$13:$E$11483))} -> 0
... A31: 44954 | B31: =SUMIFS(Timesheet!$F$13:$F$11461,Timesheet!$A$13:$A$11461,'Mês 1'!A31,Timesheet!$C$13:$C$11461,'Mês 1'!$B$40) -> 0 | C31: =SUMIFS(Timesheet!$F$13:$F$11461,Timesheet!$A$13:$A$11461,'Mês 1'!A31,Timesheet!$C$13:$C$11461,'Mês 1'!$C$40) -> 0 | D31: =SUMIFS(Timesheet!$F$13:$F$11461,Timesheet!$A$13:$A$11461,'Mês 1'!A31,Timesheet!$C$13:$C$11461,'Mês 1'!$D$40) -> 0 | E31: =SUMIFS(Timesheet!$F$13:$F$11461,Timesheet!$A$13:$A$11461,'Mês 1'!A31,Timesheet!$C$13:$C$11461,'Mês 1'!$E$40) -> 0 | F31: =SUMIFS(Timesheet!$F$13:$F$11461,Timesheet!$A$13:$A$11461,'Mês 1'!A31,Timesheet!$C$13:$C$11461,'Mês 1'!$F$40) -> 0 | G31: =SUMIFS(Timesheet!$F$13:$F$11461,Timesheet!$A$13:$A$11461,'Mês 1'!A31,Timesheet!$C$13:$C$11461,'Mês 1'!$G$40) -> 0 | H31: =SUMIFS(Timesheet!$F$13:$F$2615,Timesheet!$A$13:$A$2615,'Mês 1'!A31,Timesheet!$C$13:$C$2615,'Mês 1'!$H$3) -> 0 | I31: =SUMIFS(Timesheet!$F$13:$F$2615,Timesheet!$A$13:$A$2615,'Mês 1'!A31,Timesheet!$C$13:$C$2615,'Mês 1'!$I$3) -> 0 | J31: =SUMIFS(Timesheet!$F$13:$F$2615,Timesheet!$A$13:$A$2615,'Mês 1'!A31,Timesheet!$C$13:$C$2615,'Mês 1'!$J$3) -> 0 | K31: =SUM(B31:I31) -> 0 | L31: {=MIN(IF(Timesheet!$A$13:$A$11483='Mês 1'!A31,Timesheet!$D$13:$D$11483))} -> 0 | M31: {=MAX(IF(Timesheet!$A$13:$A$11483='Mês 1'!A31,Timesheet!$E$13:$E$11483))} -> 0 | O31: 44985 | P31: =SUMIFS(Timesheet!$F$13:$F$11461,Timesheet!$A$13:$A$11461,'Mês 1'!O31,Timesheet!$C$13:$C$11461,'Mês 1'!$B$40) -> 0 | Q31: =SUMIFS(Timesheet!$F$13:$F$11461,Timesheet!$A$13:$A$11461,'Mês 1'!O31,Timesheet!$C$13:$C$11461,'Mês 1'!$C$40) -> 0 | R31: =SUMIFS(Timesheet!$F$13:$F$11461,Timesheet!$A$13:$A$11461,'Mês 1'!O31,Timesheet!$C$13:$C$11461,'Mês 1'!$D$40) -> 0 | S31: =SUMIFS(Timesheet!$F$13:$F$11461,Timesheet!$A$13:$A$11461,'Mês 1'!O31,Timesheet!$C$13:$C$11461,'Mês 1'!$E$40) -> 0 | T31: =SUMIFS(Timesheet!$F$13:$F$11461,Timesheet!$A$13:$A$11461,'Mês 1'!O31,Timesheet!$C$13:$C$11461,'Mês 1'!$F$40) -> 0 | U31: =SUMIFS(Timesheet!$F$13:$F$11461,Timesheet!$A$13:$A$11461,'Mês 1'!O31,Timesheet!$C$13:$C$11461,'Mês 1'!$G$40) -> 0 | V31: =SUMIFS(Timesheet!$F$13:$F$11461,Timesheet!$A$13:$A$11461,'Mês 1'!O31,Timesheet!$C$13:$C$11461,'Mês 1'!$V$3) -> 0 | W31: =SUMIFS(Timesheet!$F$13:$F$11461,Timesheet!$A$13:$A$11461,'Mês 1'!O31,Timesheet!$C$13:$C$11461,'Mês 1'!$W$3) -> 0 | X31: =SUMIFS(Timesheet!$F$13:$F$11461,Timesheet!$A$13:$A$11461,'Mês 1'!O31,Timesheet!$C$13:$C$11461,'Mês 1'!$X$3) -> 0 | Y31: =SUM(P31:W31) -> 0 | Z31: {=MIN(IF(Timesheet!$A$13:$A$11483='Mês 1'!O31,Timesheet!$D$13:$D$11483))} -> 0 | AA31: {=MAX(IF(Timesheet!$A$13:$A$11483='Mês 1'!O31,Timesheet!$E$13:$E$11483))} -> 0
A32: 44955 | B32: =SUMIFS(Timesheet!$F$13:$F$11461,Timesheet!$A$13:$A$11461,'Mês 1'!A32,Timesheet!$C$13:$C$11461,'Mês 1'!$B$40) -> 0 | C32: =SUMIFS(Timesheet!$F$13:$F$11461,Timesheet!$A$13:$A$11461,'Mês 1'!A32,Timesheet!$C$13:$C$11461,'Mês 1'!$C$40) -> 0 | D32: =SUMIFS(Timesheet!$F$13:$F$11461,Timesheet!$A$13:$A$11461,'Mês 1'!A32,Timesheet!$C$13:$C$11461,'Mês 1'!$D$40) -> 0 | E32: =SUMIFS(Timesheet!$F$13:$F$11461,Timesheet!$A$13:$A$11461,'Mês 1'!A32,Timesheet!$C$13:$C$11461,'Mês 1'!$E$40) -> 0 | F32: =SUMIFS(Timesheet!$F$13:$F$11461,Timesheet!$A$13:$A$11461,'Mês 1'!A32,Timesheet!$C$13:$C$11461,'Mês 1'!$F$40) -> 0 | G32: =SUMIFS(Timesheet!$F$13:$F$11461,Timesheet!$A$13:$A$11461,'Mês 1'!A32,Timesheet!$C$13:$C$11461,'Mês 1'!$G$40) -> 0 | H32: =SUMIFS(Timesheet!$F$13:$F$2615,Timesheet!$A$13:$A$2615,'Mês 1'!A32,Timesheet!$C$13:$C$2615,'Mês 1'!$H$3) -> 0 | I32: =SUMIFS(Timesheet!$F$13:$F$2615,Timesheet!$A$13:$A$2615,'Mês 1'!A32,Timesheet!$C$13:$C$2615,'Mês 1'!$I$3) -> 0 | J32: =SUMIFS(Timesheet!$F$13:$F$2615,Timesheet!$A$13:$A$2615,'Mês 1'!A32,Timesheet!$C$13:$C$2615,'Mês 1'!$J$3) -> 0 | K32: =SUM(B32:I32) -> 0 | L32: {=MIN(IF(Timesheet!$A$13:$A$11483='Mês 1'!A32,Timesheet!$D$13:$D$11483))} -> 0 | M32: {=MAX(IF(Timesheet!$A$13:$A$11483='Mês 1'!A32,Timesheet!$E$13:$E$11483))} -> 0 | O32: Total | P32: =+SUM(P4:P31) -> 0 | Q32: =+SUM(Q4:Q31) -> 0 | R32: =+SUM(R4:R31) -> 0 | S32: =+SUM(S4:S31) -> 0 | T32: =+SUM(T4:T31) -> 0 | U32: =+SUM(U4:U31) -> 0 | V32: =+SUM(V4:V31) -> 0 | W32: =+SUM(W4:W31) -> 0 | ... Y32: =+SUM(Y4:Y31) -> 0 | Z32: =AVERAGEIF(Z4:Z31,">0") -> #DIV/0! | AA32: =AVERAGEIF(AA4:AA31, ">0") -> #DIV/0!
A33: 44956 | B33: =SUMIFS(Timesheet!$F$13:$F$11461,Timesheet!$A$13:$A$11461,'Mês 1'!A33,Timesheet!$C$13:$C$11461,'Mês 1'!$B$40) -> 0 | C33: =SUMIFS(Timesheet!$F$13:$F$11461,Timesheet!$A$13:$A$11461,'Mês 1'!A33,Timesheet!$C$13:$C$11461,'Mês 1'!$C$40) -> 0 | D33: =SUMIFS(Timesheet!$F$13:$F$11461,Timesheet!$A$13:$A$11461,'Mês 1'!A33,Timesheet!$C$13:$C$11461,'Mês 1'!$D$40) -> 0 | E33: =SUMIFS(Timesheet!$F$13:$F$11461,Timesheet!$A$13:$A$11461,'Mês 1'!A33,Timesheet!$C$13:$C$11461,'Mês 1'!$E$40) -> 0 | F33: =SUMIFS(Timesheet!$F$13:$F$11461,Timesheet!$A$13:$A$11461,'Mês 1'!A33,Timesheet!$C$13:$C$11461,'Mês 1'!$F$40) -> 0 | G33: =SUMIFS(Timesheet!$F$13:$F$11461,Timesheet!$A$13:$A$11461,'Mês 1'!A33,Timesheet!$C$13:$C$11461,'Mês 1'!$G$40) -> 0 | H33: =SUMIFS(Timesheet!$F$13:$F$2615,Timesheet!$A$13:$A$2615,'Mês 1'!A33,Timesheet!$C$13:$C$2615,'Mês 1'!$H$3) -> 0 | I33: =SUMIFS(Timesheet!$F$13:$F$2615,Timesheet!$A$13:$A$2615,'Mês 1'!A33,Timesheet!$C$13:$C$2615,'Mês 1'!$I$3) -> 0 | J33: =SUMIFS(Timesheet!$F$13:$F$2615,Timesheet!$A$13:$A$2615,'Mês 1'!A33,Timesheet!$C$13:$C$2615,'Mês 1'!$J$3) -> 0 | K33: =SUM(B33:I33) -> 0 | L33: {=MIN(IF(Timesheet!$A$13:$A$11483='Mês 1'!A33,Timesheet!$D$13:$D$11483))} -> 0 | M33: {=MAX(IF(Timesheet!$A$13:$A$11483='Mês 1'!A33,Timesheet!$E$13:$E$11483))} -> 0
A34: 44957 | B34: =SUMIFS(Timesheet!$F$13:$F$11461,Timesheet!$A$13:$A$11461,'Mês 1'!A34,Timesheet!$C$13:$C$11461,'Mês 1'!$B$40) -> 0 | C34: =SUMIFS(Timesheet!$F$13:$F$11461,Timesheet!$A$13:$A$11461,'Mês 1'!A34,Timesheet!$C$13:$C$11461,'Mês 1'!$C$40) -> 0 | D34: =SUMIFS(Timesheet!$F$13:$F$11461,Timesheet!$A$13:$A$11461,'Mês 1'!A34,Timesheet!$C$13:$C$11461,'Mês 1'!$D$40) -> 0 | E34: =SUMIFS(Timesheet!$F$13:$F$11461,Timesheet!$A$13:$A$11461,'Mês 1'!A34,Timesheet!$C$13:$C$11461,'Mês 1'!$E$40) -> 0 | F34: =SUMIFS(Timesheet!$F$13:$F$11461,Timesheet!$A$13:$A$11461,'Mês 1'!A34,Timesheet!$C$13:$C$11461,'Mês 1'!$F$40) -> 0 | G34: =SUMIFS(Timesheet!$F$13:$F$11461,Timesheet!$A$13:$A$11461,'Mês 1'!A34,Timesheet!$C$13:$C$11461,'Mês 1'!$G$40) -> 0 | H34: =SUMIFS(Timesheet!$F$13:$F$2615,Timesheet!$A$13:$A$2615,'Mês 1'!A34,Timesheet!$C$13:$C$2615,'Mês 1'!$H$3) -> 0 | I34: =SUMIFS(Timesheet!$F$13:$F$2615,Timesheet!$A$13:$A$2615,'Mês 1'!A34,Timesheet!$C$13:$C$2615,'Mês 1'!$I$3) -> 0 | J34: =SUMIFS(Timesheet!$F$13:$F$2615,Timesheet!$A$13:$A$2615,'Mês 1'!A34,Timesheet!$C$13:$C$2615,'Mês 1'!$J$3) -> 0 | K34: =SUM(B34:I34) -> 0 | L34: {=MIN(IF(Timesheet!$A$13:$A$11483='Mês 1'!A34,Timesheet!$D$13:$D$11483))} -> 0 | M34: {=MAX(IF(Timesheet!$A$13:$A$11483='Mês 1'!A34,Timesheet!$E$13:$E$11483))} -> 0
A35: Total | B35: =+SUM(B4:B34) -> 0 | C35: =+SUM(C4:C34) -> 0 | D35: =+SUM(D4:D34) -> 0 | E35: =+SUM(E4:E34) -> 0 | F35: =+SUM(F4:F34) -> 0 | G35: =+SUM(G4:G34) -> 0 | H35: =+SUM(H4:H34) -> 0 | I35: =+SUM(I4:I34) -> 0 | ... K35: =+SUM(K4:K34) -> 0 | L35: =AVERAGEIF(L4:L34,">0") -> #DIV/0! | M35: =AVERAGEIF(M4:M34, ">0") -> #DIV/0!
A39: Mês | B39: Março | O39: Mês | P39: Maio | AC39: Mês | AD39: Julho | AQ39: Mês | AR39: Setembro | BE39: Mês | BF39: Novembro
A40: Data | B40: Análise | C40: Elaboração | D40: Gestão | E40: Outro | F40: Reunião | G40: Revisão | H40: Suporte | I40: Execução | J40: Pesquisa | K40: Total | L40: Entrada | M40: Saída | O40: Data | P40: Análise | Q40: Elaboração | R40: Gestão | S40: Outro | T40: Reunião | U40: Revisão | V40: Suporte | W40: Execução | X40: Pesquisa | Y40: Total | Z40: Entrada | AA40: Saída | AC40: Data | AD40: Análise | AE40: Elaboração | AF40: Gestão | AG40: Outro | AH40: Reunião | AI40: Revisão | AJ40: Suporte | AK40: Execução | AL40: Pesquisa | AM40: Total | AN40: Entrada | AO40: Saída | AQ40: Data | AR40: Análise | AS40: Elaboração | AT40: Gestão | AU40: Outro | AV40: Reunião | AW40: Revisão | AX40: Suporte | AY40: Execução | AZ40: Pesquisa | BA40: Total | BB40: Entrada | BC40: Saída | BE40: Data | BF40: Análise | BG40: Elaboração | BH40: Gestão | BI40: Outro | BJ40: Reunião | BK40: Revisão | BL40: Suporte | BM40: Execução | BN40: Pesquisa | BO40: Total | BP40: Entrada | BQ40: Saída
A41: 44986 | B41: =SUMIFS(Timesheet!$F$13:$F$11461,Timesheet!$A$13:$A$11461,'Mês 1'!A41,Timesheet!$C$13:$C$11461,'Mês 1'!$B$40) -> 0 | C41: =SUMIFS(Timesheet!$F$13:$F$11461,Timesheet!$A$13:$A$11461,'Mês 1'!A41,Timesheet!$C$13:$C$11461,'Mês 1'!$C$40) -> 0 | D41: =SUMIFS(Timesheet!$F$13:$F$11461,Timesheet!$A$13:$A$11461,'Mês 1'!A41,Timesheet!$C$13:$C$11461,'Mês 1'!$D$40) -> 0 | E41: =SUMIFS(Timesheet!$F$13:$F$11461,Timesheet!$A$13:$A$11461,'Mês 1'!A41,Timesheet!$C$13:$C$11461,'Mês 1'!$E$40) -> 0 | F41: =SUMIFS(Timesheet!$F$13:$F$11461,Timesheet!$A$13:$A$11461,'Mês 1'!A41,Timesheet!$C$13:$C$11461,'Mês 1'!$F$40) -> 0 | G41: =SUMIFS(Timesheet!$F$13:$F$11461,Timesheet!$A$13:$A$11461,'Mês 1'!A41,Timesheet!$C$13:$C$11461,'Mês 1'!$G$40) -> 0 | H41: =SUMIFS(Timesheet!$F$13:$F$11461,Timesheet!$A$13:$A$11461,'Mês 1'!A41,Timesheet!$C$13:$C$11461,'Mês 1'!$H$40) -> 0 | I41: =SUMIFS(Timesheet!$F$13:$F$11461,Timesheet!$A$13:$A$11461,'Mês 1'!A41,Timesheet!$C$13:$C$11461,'Mês 1'!$I$40) -> 0 | J41: =SUMIFS(Timesheet!$F$13:$F$11461,Timesheet!$A$13:$A$11461,'Mês 1'!A41,Timesheet!$C$13:$C$11461,'Mês 1'!$J$40) -> 0 | K41: =SUM(B41:I41) -> 0 | L41: {=MIN(IF(Timesheet!$A$13:$A$11483='Mês 1'!A41,Timesheet!$D$13:$D$11483))} -> 0 | M41: {=MAX(IF(Timesheet!$A$13:$A$11483='Mês 1'!A41,Timesheet!$E$13:$E$11483))} -> 0 | O41: 45047 | P41: =SUMIFS(Timesheet!$F$13:$F$11461,Timesheet!$A$13:$A$11461,'Mês 1'!O41,Timesheet!$C$13:$C$11461,'Mês 1'!$P$40) -> 0 | Q41: =SUMIFS(Timesheet!$F$13:$F$11461,Timesheet!$A$13:$A$11461,'Mês 1'!O41,Timesheet!$C$13:$C$11461,'Mês 1'!$Q$40) -> 0 | R41: =SUMIFS(Timesheet!$F$13:$F$11461,Timesheet!$A$13:$A$11461,'Mês 1'!O41,Timesheet!$C$13:$C$11461,'Mês 1'!$R$40) -> 0 | S41: =SUMIFS(Timesheet!$F$13:$F$11461,Timesheet!$A$13:$A$11461,'Mês 1'!O41,Timesheet!$C$13:$C$11461,'Mês 1'!$S$40) -> 0 | T41: =SUMIFS(Timesheet!$F$13:$F$11461,Timesheet!$A$13:$A$11461,'Mês 1'!O41,Timesheet!$C$13:$C$11461,'Mês 1'!$T$40) -> 0 | U41: =SUMIFS(Timesheet!$F$13:$F$11461,Timesheet!$A$13:$A$11461,'Mês 1'!O41,Timesheet!$C$13:$C$11461,'Mês 1'!$U$40) -> 0 | V41: =SUMIFS(Timesheet!$F$13:$F$11461,Timesheet!$A$13:$A$11461,'Mês 1'!O41,Timesheet!$C$13:$C$11461,'Mês 1'!$V$40) -> 0 | W41: =SUMIFS(Timesheet!$F$13:$F$11461,Timesheet!$A$13:$A$11461,'Mês 1'!O41,Timesheet!$C$13:$C$11461,'Mês 1'!$W$40) -> 0 | X41: =SUMIFS(Timesheet!$F$13:$F$11461,Timesheet!$A$13:$A$11461,'Mês 1'!O41,Timesheet!$C$13:$C$11461,'Mês 1'!$X$40) -> 0 | Y41: =SUM(P41:W41) -> 0 | Z41: {=MIN(IF(Timesheet!$A$13:$A$11483='Mês 1'!O41,Timesheet!$D$13:$D$11483))} -> 0 | AA41: {=MAX(IF(Timesheet!$A$13:$A$11483='Mês 1'!O41,Timesheet!$E$13:$E$11483))} -> 0 | AC41: 45108 | AD41: =SUMIFS(Timesheet!$F$13:$F$11461,Timesheet!$A$13:$A$11461,'Mês 1'!AC41,Timesheet!$C$13:$C$11461,'Mês 1'!$AD$40) -> 0 | AE41: =SUMIFS(Timesheet!$F$13:$F$11461,Timesheet!$A$13:$A$11461,'Mês 1'!AC41,Timesheet!$C$13:$C$11461,'Mês 1'!$AE$40) -> 0 | AF41: =SUMIFS(Timesheet!$F$13:$F$11461,Timesheet!$A$13:$A$11461,'Mês 1'!AC41,Timesheet!$C$13:$C$11461,'Mês 1'!$AF$40) -> 0 | AG41: =SUMIFS(Timesheet!$F$13:$F$11461,Timesheet!$A$13:$A$11461,'Mês 1'!AC41,Timesheet!$C$13:$C$11461,'Mês 1'!$AG$40) -> 0 | AH41: =SUMIFS(Timesheet!$F$13:$F$11461,Timesheet!$A$13:$A$11461,'Mês 1'!AC41,Timesheet!$C$13:$C$11461,'Mês 1'!$AH$40) -> 0 | AI41: =SUMIFS(Timesheet!$F$13:$F$11461,Timesheet!$A$13:$A$11461,'Mês 1'!AC41,Timesheet!$C$13:$C$11461,'Mês 1'!$AI$40) -> 0 | AJ41: =SUMIFS(Timesheet!$F$13:$F$11461,Timesheet!$A$13:$A$11461,'Mês 1'!AC41,Timesheet!$C$13:$C$11461,'Mês 1'!$AJ$40) -> 0 | AK41: =SUMIFS(Timesheet!$F$13:$F$11461,Timesheet!$A$13:$A$11461,'Mês 1'!AC41,Timesheet!$C$13:$C$11461,'Mês 1'!$AK$40) -> 0 | AL41: =SUMIFS(Timesheet!$F$13:$F$11461,Timesheet!$A$13:$A$11461,'Mês 1'!AC41,Timesheet!$C$13:$C$11461,'Mês 1'!$AL$40) -> 0 | AM41: =SUM(AD41:AK41) -> 0 | AN41: {=MIN(IF(Timesheet!$A$13:$A$11483='Mês 1'!AC41,Timesheet!$D$13:$D$11483))} -> 0 | AO41: {=MAX(IF(Timesheet!$A$13:$A$11483='Mês 1'!AC41,Timesheet!$E$13:$E$11483))} -> 0 | AQ41: 45170 | AR41: =SUMIFS(Timesheet!$F$13:$F$11461,Timesheet!$A$13:$A$11461,'Mês 1'!AQ41,Timesheet!$C$13:$C$11461,'Mês 1'!$AR$40) -> 0 | AS41: =SUMIFS(Timesheet!$F$13:$F$11461,Timesheet!$A$13:$A$11461,'Mês 1'!AQ41,Timesheet!$C$13:$C$11461,'Mês 1'!$AS$40) -> 0 | AT41: =SUMIFS(Timesheet!$F$13:$F$11461,Timesheet!$A$13:$A$11461,'Mês 1'!AQ41,Timesheet!$C$13:$C$11461,'Mês 1'!$AT$40) -> 0 | AU41: =SUMIFS(Timesheet!$F$13:$F$11461,Timesheet!$A$13:$A$11461,'Mês 1'!AQ41,Timesheet!$C$13:$C$11461,'Mês 1'!$AU$40) -> 0 | AV41: =SUMIFS(Timesheet!$F$13:$F$11461,Timesheet!$A$13:$A$11461,'Mês 1'!AQ41,Timesheet!$C$13:$C$11461,'Mês 1'!$AV$40) -> 0 | AW41: =SUMIFS(Timesheet!$F$13:$F$11461,Timesheet!$A$13:$A$11461,'Mês 1'!AQ41,Timesheet!$C$13:$C$11461,'Mês 1'!$AW$40) -> 0 | AX41: =SUMIFS(Timesheet!$F$13:$F$11461,Timesheet!$A$13:$A$11461,'Mês 1'!AQ41,Timesheet!$C$13:$C$11461,'Mês 1'!$AX$40) -> 0 | AY41: =SUMIFS(Timesheet!$F$13:$F$11461,Timesheet!$A$13:$A$11461,'Mês 1'!AQ41,Timesheet!$C$13:$C$11461,'Mês 1'!$AY$40) -> 0 | AZ41: =SUMIFS(Timesheet!$F$13:$F$11461,Timesheet!$A$13:$A$11461,'Mês 1'!AQ41,Timesheet!$C$13:$C$11461,'Mês 1'!$AZ$40) -> 0 | BA41: =SUM(AR41:AY41) -> 0 | BB41: {=MIN(IF(Timesheet!$A$13:$A$11483='Mês 1'!AQ41,Timesheet!$D$13:$D$11483))} -> 0 | BC41: {=MAX(IF(Timesheet!$A$13:$A$11483='Mês 1'!AQ41,Timesheet!$E$13:$E$11483))} -> 0 | BE41: 45231 | BF41: =SUMIFS(Timesheet!$F$13:$F$11461,Timesheet!$A$13:$A$11461,'Mês 1'!BE41,Timesheet!$C$13:$C$11461,'Mês 1'!$BF$40) -> 0 | BG41: =SUMIFS(Timesheet!$F$13:$F$11461,Timesheet!$A$13:$A$11461,'Mês 1'!BE41,Timesheet!$C$13:$C$11461,'Mês 1'!$BG$40) -> 0 | BH41: =SUMIFS(Timesheet!$F$13:$F$11461,Timesheet!$A$13:$A$11461,'Mês 1'!BE41,Timesheet!$C$13:$C$11461,'Mês 1'!$BH$40) -> 0 | BI41: =SUMIFS(Timesheet!$F$13:$F$11461,Timesheet!$A$13:$A$11461,'Mês 1'!BE41,Timesheet!$C$13:$C$11461,'Mês 1'!$BI$40) -> 0 | BJ41: =SUMIFS(Timesheet!$F$13:$F$11461,Timesheet!$A$13:$A$11461,'Mês 1'!BE41,Timesheet!$C$13:$C$11461,'Mês 1'!$BJ$40) -> 0 | BK41: =SUMIFS(Timesheet!$F$13:$F$11461,Timesheet!$A$13:$A$11461,'Mês 1'!BE41,Timesheet!$C$13:$C$11461,'Mês 1'!$BK$40) -> 0 | BL41: =SUMIFS(Timesheet!$F$13:$F$11461,Timesheet!$A$13:$A$11461,'Mês 1'!BE41,Timesheet!$C$13:$C$11461,'Mês 1'!$BL$40) -> 0 | BM41: =SUMIFS(Timesheet!$F$13:$F$11461,Timesheet!$A$13:$A$11461,'Mês 1'!BE41,Timesheet!$C$13:$C$11461,'Mês 1'!$BM$40) -> 0 | BN41: =SUMIFS(Timesheet!$F$13:$F$11461,Timesheet!$A$13:$A$11461,'Mês 1'!BE41,Timesheet!$C$13:$C$11461,'Mês 1'!$BN$40) -> 0 | BO41: =SUM(BF41:BM41) -> 0 | BP41: {=MIN(IF(Timesheet!$A$13:$A$11483='Mês 1'!BE41,Timesheet!$D$13:$D$11483))} -> 0 | BQ41: {=MAX(IF(Timesheet!$A$13:$A$11483='Mês 1'!BE41,Timesheet!$E$13:$E$11483))} -> 0
A42: 44987 | B42: =SUMIFS(Timesheet!$F$13:$F$11461,Timesheet!$A$13:$A$11461,'Mês 1'!A42,Timesheet!$C$13:$C$11461,'Mês 1'!$B$40) -> 0 | C42: =SUMIFS(Timesheet!$F$13:$F$11461,Timesheet!$A$13:$A$11461,'Mês 1'!A42,Timesheet!$C$13:$C$11461,'Mês 1'!$C$40) -> 0 | D42: =SUMIFS(Timesheet!$F$13:$F$11461,Timesheet!$A$13:$A$11461,'Mês 1'!A42,Timesheet!$C$13:$C$11461,'Mês 1'!$D$40) -> 0 | E42: =SUMIFS(Timesheet!$F$13:$F$11461,Timesheet!$A$13:$A$11461,'Mês 1'!A42,Timesheet!$C$13:$C$11461,'Mês 1'!$E$40) -> 0 | F42: =SUMIFS(Timesheet!$F$13:$F$11461,Timesheet!$A$13:$A$11461,'Mês 1'!A42,Timesheet!$C$13:$C$11461,'Mês 1'!$F$40) -> 0 | G42: =SUMIFS(Timesheet!$F$13:$F$11461,Timesheet!$A$13:$A$11461,'Mês 1'!A42,Timesheet!$C$13:$C$11461,'Mês 1'!$G$40) -> 0 | H42: =SUMIFS(Timesheet!$F$13:$F$11461,Timesheet!$A$13:$A$11461,'Mês 1'!A42,Timesheet!$C$13:$C$11461,'Mês 1'!$H$40) -> 0 | I42: =SUMIFS(Timesheet!$F$13:$F$11461,Timesheet!$A$13:$A$11461,'Mês 1'!A42,Timesheet!$C$13:$C$11461,'Mês 1'!$I$40) -> 0 | J42: =SUMIFS(Timesheet!$F$13:$F$11461,Timesheet!$A$13:$A$11461,'Mês 1'!A42,Timesheet!$C$13:$C$11461,'Mês 1'!$J$40) -> 0 | K42: =SUM(B42:I42) -> 0 | L42: {=MIN(IF(Timesheet!$A$13:$A$11483='Mês 1'!A42,Timesheet!$D$13:$D$11483))} -> 0 | M42: {=MAX(IF(Timesheet!$A$13:$A$11483='Mês 1'!A42,Timesheet!$E$13:$E$11483))} -> 0 | O42: 45048 | P42: =SUMIFS(Timesheet!$F$13:$F$11461,Timesheet!$A$13:$A$11461,'Mês 1'!O42,Timesheet!$C$13:$C$11461,'Mês 1'!$P$40) -> 0 | Q42: =SUMIFS(Timesheet!$F$13:$F$11461,Timesheet!$A$13:$A$11461,'Mês 1'!O42,Timesheet!$C$13:$C$11461,'Mês 1'!$Q$40) -> 0 | R42: =SUMIFS(Timesheet!$F$13:$F$11461,Timesheet!$A$13:$A$11461,'Mês 1'!O42,Timesheet!$C$13:$C$11461,'Mês 1'!$R$40) -> 0 | S42: =SUMIFS(Timesheet!$F$13:$F$11461,Timesheet!$A$13:$A$11461,'Mês 1'!O42,Timesheet!$C$13:$C$11461,'Mês 1'!$S$40) -> 0 | T42: =SUMIFS(Timesheet!$F$13:$F$11461,Timesheet!$A$13:$A$11461,'Mês 1'!O42,Timesheet!$C$13:$C$11461,'Mês 1'!$T$40) -> 0 | U42: =SUMIFS(Timesheet!$F$13:$F$11461,Timesheet!$A$13:$A$11461,'Mês 1'!O42,Timesheet!$C$13:$C$11461,'Mês 1'!$U$40) -> 0 | V42: =SUMIFS(Timesheet!$F$13:$F$11461,Timesheet!$A$13:$A$11461,'Mês 1'!O42,Timesheet!$C$13:$C$11461,'Mês 1'!$V$40) -> 0 | W42: =SUMIFS(Timesheet!$F$13:$F$11461,Timesheet!$A$13:$A$11461,'Mês 1'!O42,Timesheet!$C$13:$C$11461,'Mês 1'!$W$40) -> 0 | X42: =SUMIFS(Timesheet!$F$13:$F$11461,Timesheet!$A$13:$A$11461,'Mês 1'!O42,Timesheet!$C$13:$C$11461,'Mês 1'!$X$40) -> 0 | Y42: =SUM(P42:W42) -> 0 | Z42: {=MIN(IF(Timesheet!$A$13:$A$11483='Mês 1'!O42,Timesheet!$D$13:$D$11483))} -> 0 | AA42: {=MAX(IF(Timesheet!$A$13:$A$11483='Mês 1'!O42,Timesheet!$E$13:$E$11483))} -> 0 | AC42: 45109 | AD42: =SUMIFS(Timesheet!$F$13:$F$11461,Timesheet!$A$13:$A$11461,'Mês 1'!AC42,Timesheet!$C$13:$C$11461,'Mês 1'!$AD$40) -> 0 | AE42: =SUMIFS(Timesheet!$F$13:$F$11461,Timesheet!$A$13:$A$11461,'Mês 1'!AC42,Timesheet!$C$13:$C$11461,'Mês 1'!$AE$40) -> 0 | AF42: =SUMIFS(Timesheet!$F$13:$F$11461,Timesheet!$A$13:$A$11461,'Mês 1'!AC42,Timesheet!$C$13:$C$11461,'Mês 1'!$AF$40) -> 0 | AG42: =SUMIFS(Timesheet!$F$13:$F$11461,Timesheet!$A$13:$A$11461,'Mês 1'!AC42,Timesheet!$C$13:$C$11461,'Mês 1'!$AG$40) -> 0 | AH42: =SUMIFS(Timesheet!$F$13:$F$11461,Timesheet!$A$13:$A$11461,'Mês 1'!AC42,Timesheet!$C$13:$C$11461,'Mês 1'!$AH$40) -> 0 | AI42: =SUMIFS(Timesheet!$F$13:$F$11461,Timesheet!$A$13:$A$11461,'Mês 1'!AC42,Timesheet!$C$13:$C$11461,'Mês 1'!$AI$40) -> 0 | AJ42: =SUMIFS(Timesheet!$F$13:$F$11461,Timesheet!$A$13:$A$11461,'Mês 1'!AC42,Timesheet!$C$13:$C$11461,'Mês 1'!$AJ$40) -> 0 | AK42: =SUMIFS(Timesheet!$F$13:$F$11461,Timesheet!$A$13:$A$11461,'Mês 1'!AC42,Timesheet!$C$13:$C$11461,'Mês 1'!$AK$40) -> 0 | AL42: =SUMIFS(Timesheet!$F$13:$F$11461,Timesheet!$A$13:$A$11461,'Mês 1'!AC42,Timesheet!$C$13:$C$11461,'Mês 1'!$AL$40) -> 0 | AM42: =SUM(AD42:AK42) -> 0 | AN42: {=MIN(IF(Timesheet!$A$13:$A$11483='Mês 1'!AC42,Timesheet!$D$13:$D$11483))} -> 0 | AO42: {=MAX(IF(Timesheet!$A$13:$A$11483='Mês 1'!AC42,Timesheet!$E$13:$E$11483))} -> 0 | AQ42: 45171 | AR42: =SUMIFS(Timesheet!$F$13:$F$11461,Timesheet!$A$13:$A$11461,'Mês 1'!AQ42,Timesheet!$C$13:$C$11461,'Mês 1'!$AR$40) -> 0 | AS42: =SUMIFS(Timesheet!$F$13:$F$11461,Timesheet!$A$13:$A$11461,'Mês 1'!AQ42,Timesheet!$C$13:$C$11461,'Mês 1'!$AS$40) -> 0 | AT42: =SUMIFS(Timesheet!$F$13:$F$11461,Timesheet!$A$13:$A$11461,'Mês 1'!AQ42,Timesheet!$C$13:$C$11461,'Mês 1'!$AT$40) -> 0 | AU42: =SUMIFS(Timesheet!$F$13:$F$11461,Timesheet!$A$13:$A$11461,'Mês 1'!AQ42,Timesheet!$C$13:$C$11461,'Mês 1'!$AU$40) -> 0 | AV42: =SUMIFS(Timesheet!$F$13:$F$11461,Timesheet!$A$13:$A$11461,'Mês 1'!AQ42,Timesheet!$C$13:$C$11461,'Mês 1'!$AV$40) -> 0 | AW42: =SUMIFS(Timesheet!$F$13:$F$11461,Timesheet!$A$13:$A$11461,'Mês 1'!AQ42,Timesheet!$C$13:$C$11461,'Mês 1'!$AW$40) -> 0 | AX42: =SUMIFS(Timesheet!$F$13:$F$11461,Timesheet!$A$13:$A$11461,'Mês 1'!AQ42,Timesheet!$C$13:$C$11461,'Mês 1'!$AX$40) -> 0 | AY42: =SUMIFS(Timesheet!$F$13:$F$11461,Timesheet!$A$13:$A$11461,'Mês 1'!AQ42,Timesheet!$C$13:$C$11461,'Mês 1'!$AY$40) -> 0 | AZ42: =SUMIFS(Timesheet!$F$13:$F$11461,Timesheet!$A$13:$A$11461,'Mês 1'!AQ42,Timesheet!$C$13:$C$11461,'Mês 1'!$AZ$40) -> 0 | BA42: =SUM(AR42:AY42) -> 0 | BB42: {=MIN(IF(Timesheet!$A$13:$A$11483='Mês 1'!AQ42,Timesheet!$D$13:$D$11483))} -> 0 | BC42: {=MAX(IF(Timesheet!$A$13:$A$11483='Mês 1'!AQ42,Timesheet!$E$13:$E$11483))} -> 0 | BE42: 45232 | BF42: =SUMIFS(Timesheet!$F$13:$F$11461,Timesheet!$A$13:$A$11461,'Mês 1'!BE42,Timesheet!$C$13:$C$11461,'Mês 1'!$BF$40) -> 0 | BG42: =SUMIFS(Timesheet!$F$13:$F$11461,Timesheet!$A$13:$A$11461,'Mês 1'!BE42,Timesheet!$C$13:$C$11461,'Mês 1'!$BG$40) -> 0 | BH42: =SUMIFS(Timesheet!$F$13:$F$11461,Timesheet!$A$13:$A$11461,'Mês 1'!BE42,Timesheet!$C$13:$C$11461,'Mês 1'!$BH$40) -> 0 | BI42: =SUMIFS(Timesheet!$F$13:$F$11461,Timesheet!$A$13:$A$11461,'Mês 1'!BE42,Timesheet!$C$13:$C$11461,'Mês 1'!$BI$40) -> 0 | BJ42: =SUMIFS(Timesheet!$F$13:$F$11461,Timesheet!$A$13:$A$11461,'Mês 1'!BE42,Timesheet!$C$13:$C$11461,'Mês 1'!$BJ$40) -> 0 | BK42: =SUMIFS(Timesheet!$F$13:$F$11461,Timesheet!$A$13:$A$11461,'Mês 1'!BE42,Timesheet!$C$13:$C$11461,'Mês 1'!$BK$40) -> 0 | BL42: =SUMIFS(Timesheet!$F$13:$F$11461,Timesheet!$A$13:$A$11461,'Mês 1'!BE42,Timesheet!$C$13:$C$11461,'Mês 1'!$BL$40) -> 0 | BM42: =SUMIFS(Timesheet!$F$13:$F$11461,Timesheet!$A$13:$A$11461,'Mês 1'!BE42,Timesheet!$C$13:$C$11461,'Mês 1'!$BM$40) -> 0 | BN42: =SUMIFS(Timesheet!$F$13:$F$11461,Timesheet!$A$13:$A$11461,'Mês 1'!BE42,Timesheet!$C$13:$C$11461,'Mês 1'!$BN$40) -> 0 | BO42: =SUM(BF42:BM42) -> 0 | BP42: {=MIN(IF(Timesheet!$A$13:$A$11483='Mês 1'!BE42,Timesheet!$D$13:$D$11483))} -> 0 | BQ42: {=MAX(IF(Timesheet!$A$13:$A$11483='Mês 1'!BE42,Timesheet!$E$13:$E$11483))} -> 0
